2024-10-13 19:39:17.654288: I external/local_xla/xla/tsl/cuda/cudart_stub.cc:32] Could not find cuda drivers on your machine, GPU will not be used.
2024-10-13 19:39:17.663423: I external/local_xla/xla/tsl/cuda/cudart_stub.cc:32] Could not find cuda drivers on your machine, GPU will not be used.
2024-10-13 19:39:17.693923: E external/local_xla/xla/stream_executor/cuda/cuda_fft.cc:485] Unable to register cuFFT factory: Attempting to register factory for plugin cuFFT when one has already been registered
2024-10-13 19:39:17.744434: E external/local_xla/xla/stream_executor/cuda/cuda_dnn.cc:8454] Unable to register cuDNN factory: Attempting to register factory for plugin cuDNN when one has already been registered
2024-10-13 19:39:17.758404: E external/local_xla/xla/stream_executor/cuda/cuda_blas.cc:1452] Unable to register cuBLAS factory: Attempting to register factory for plugin cuBLAS when one has already been registered
2024-10-13 19:39:17.796373: I tensorflow/core/platform/cpu_feature_guard.cc:210] This TensorFlow binary is optimized to use available CPU instructions in performance-critical operations.
To enable the following instructions: AVX2 AVX512F FMA, in other operations, rebuild TensorFlow with the appropriate compiler flags.
2024-10-13 19:39:19.960831: W tensorflow/compiler/tf2tensorrt/utils/py_utils.cc:38] TF-TRT Warning: Could not find TensorRT
Found 4 images belonging to 2 classes.
Found 4 images belonging to 2 classes.
/usr/local/lib/python3.10/dist-packages/keras/src/trainers/data_adapters/py_dataset_adapter.py:121: UserWarning: Your `PyDataset` class should call `super().__init__(**kwargs)` in its constructor. `**kwargs` can include `workers`, `use_multiprocessing`, `max_queue_size`. Do not pass these arguments to `fit()`, as they will be ignored.
  self._warn_if_super_not_called()
Iniciando o treinamento do modelo
Traceback (most recent call last):
  File "/home/user/gpr_ai_project/cnn_model.py", line 115, in <module>
    cnn_gpr.train(train_dir='data/train', validation_dir='data/validation', epochs=5, batch_size=2)
  File "/home/user/gpr_ai_project/cnn_model.py", line 72, in train
    history = self.model.fit(
  File "/usr/local/lib/python3.10/dist-packages/keras/src/utils/traceback_utils.py", line 122, in error_handler
    raise e.with_traceback(filtered_tb) from None
  File "/usr/local/lib/python3.10/dist-packages/optree/ops.py", line 747, in tree_map
    return treespec.unflatten(map(func, *flat_args))
ValueError: None values not supported.
