2024-10-13 19:57:39.392687: I external/local_xla/xla/tsl/cuda/cudart_stub.cc:32] Could not find cuda drivers on your machine, GPU will not be used.
2024-10-13 19:57:39.397282: I external/local_xla/xla/tsl/cuda/cudart_stub.cc:32] Could not find cuda drivers on your machine, GPU will not be used.
2024-10-13 19:57:39.411491: E external/local_xla/xla/stream_executor/cuda/cuda_fft.cc:485] Unable to register cuFFT factory: Attempting to register factory for plugin cuFFT when one has already been registered
2024-10-13 19:57:39.434715: E external/local_xla/xla/stream_executor/cuda/cuda_dnn.cc:8454] Unable to register cuDNN factory: Attempting to register factory for plugin cuDNN when one has already been registered
2024-10-13 19:57:39.441500: E external/local_xla/xla/stream_executor/cuda/cuda_blas.cc:1452] Unable to register cuBLAS factory: Attempting to register factory for plugin cuBLAS when one has already been registered
2024-10-13 19:57:39.459031: I tensorflow/core/platform/cpu_feature_guard.cc:210] This TensorFlow binary is optimized to use available CPU instructions in performance-critical operations.
To enable the following instructions: AVX2 AVX512F FMA, in other operations, rebuild TensorFlow with the appropriate compiler flags.
2024-10-13 19:57:40.662115: W tensorflow/compiler/tf2tensorrt/utils/py_utils.cc:38] TF-TRT Warning: Could not find TensorRT
/usr/local/lib/python3.10/dist-packages/keras/src/layers/convolutional/base_conv.py:107: UserWarning: Do not pass an `input_shape`/`input_dim` argument to a layer. When using Sequential models, prefer using an `Input(shape)` object as the first layer in the model instead.
  super().__init__(activity_regularizer=activity_regularizer, **kwargs)
2024-10-13 19:57:42.232485: W external/local_tsl/tsl/framework/cpu_allocator_impl.cc:83] Allocation of 58982400 exceeds 10% of free system memory.
2024-10-13 19:57:42.251692: W external/local_tsl/tsl/framework/cpu_allocator_impl.cc:83] Allocation of 58982400 exceeds 10% of free system memory.
2024-10-13 19:57:42.260230: W external/local_tsl/tsl/framework/cpu_allocator_impl.cc:83] Allocation of 58982400 exceeds 10% of free system memory.
Traceback (most recent call last):
  File "/usr/local/bin/uvicorn", line 8, in <module>
    sys.exit(main())
  File "/usr/local/lib/python3.10/dist-packages/click/core.py", line 1157, in __call__
    return self.main(*args, **kwargs)
  File "/usr/local/lib/python3.10/dist-packages/click/core.py", line 1078, in main
    rv = self.invoke(ctx)
  File "/usr/local/lib/python3.10/dist-packages/click/core.py", line 1434, in invoke
    return ctx.invoke(self.callback, **ctx.params)
  File "/usr/local/lib/python3.10/dist-packages/click/core.py", line 783, in invoke
    return __callback(*args, **kwargs)
  File "/usr/local/lib/python3.10/dist-packages/uvicorn/main.py", line 412, in main
    run(
  File "/usr/local/lib/python3.10/dist-packages/uvicorn/main.py", line 579, in run
    server.run()
  File "/usr/local/lib/python3.10/dist-packages/uvicorn/server.py", line 65, in run
    return asyncio.run(self.serve(sockets=sockets))
  File "/usr/lib/python3.10/asyncio/runners.py", line 44, in run
    return loop.run_until_complete(main)
  File "/usr/lib/python3.10/asyncio/base_events.py", line 649, in run_until_complete
    return future.result()
  File "/usr/local/lib/python3.10/dist-packages/uvicorn/server.py", line 69, in serve
    await self._serve(sockets)
  File "/usr/local/lib/python3.10/dist-packages/uvicorn/server.py", line 76, in _serve
    config.load()
  File "/usr/local/lib/python3.10/dist-packages/uvicorn/config.py", line 434, in load
    self.loaded_app = import_from_string(self.app)
  File "/usr/local/lib/python3.10/dist-packages/uvicorn/importer.py", line 19, in import_from_string
    module = importlib.import_module(module_str)
  File "/usr/lib/python3.10/importlib/__init__.py", line 126, in import_module
    return _bootstrap._gcd_import(name[level:], package, level)
  File "<frozen importlib._bootstrap>", line 1050, in _gcd_import
  File "<frozen importlib._bootstrap>", line 1027, in _find_and_load
  File "<frozen importlib._bootstrap>", line 1006, in _find_and_load_unlocked
  File "<frozen importlib._bootstrap>", line 688, in _load_unlocked
  File "<frozen importlib._bootstrap_external>", line 883, in exec_module
  File "<frozen importlib._bootstrap>", line 241, in _call_with_frames_removed
  File "/home/user/gpr_ai_project/web_app.py", line 89, in <module>
    ai = AdvancedGPRAI()
  File "/home/user/gpr_ai_project/web_app.py", line 23, in __init__
    self._create_db()
  File "/home/user/gpr_ai_project/web_app.py", line 30, in _create_db
    cursor.execute('''
sqlite3.DatabaseError: file is not a database
